Workbook

Sheet harga saham
A1: DATA HARGA SAHAM KBMI IV | G1: DIVIDEN KBMI IV
A4: TAHUN | B4: HARGA SAHAM | G4: TAHUN | H4: DIVIDEN
B5: BBCA | C5: BBRI | D5: BBNI | E5: BMRI | H5: BBCA | I5: BBRI | J5: BBNI | K5: BMRI
A6: 2012 | B6: 1820 | C6: 1390 | D6: 1850 | E6: 2025 | G6: 2013 | H6: 116 | I6: 225.232 | J6: 113.35 | K6: 199.33799
A7: 2013 | B7: 1920 | C7: 1450 | D7: 1975 | E7: 1962.5 | G7: 2014 | H7: 125 | I7: 257.3271 | J7: 145.71 | K7: 234.04825
A8: 2014 | B8: 2625 | C8: 2330 | D8: 3050 | E8: 2693.75 | G8: 2015 | H8: 153 | I8: 294.801 | J8: 144.54965 | K8: 212.91292
A9: 2015 | B9: 2660 | C9: 2285 | D9: 2945 | E9: 2312.5 | G9: 2016 | H9: 175 | I9: 311.6613 | J9: 122.53382 | K9: 261.44958
A10: 2016 | B10: 3100 | C10: 2335 | D10: 2762.5 | E10: 2893.75 | G10: 2017 | H10: 210 | I10: 428.60549 | J10: 212.80685 | K10: 266.26947
A11: 2017 | B11: 4380 | C11: 3640 | D11: 4950 | E11: 4000 | G11: 2018 | H11: 260 | I11: 106.74687 | J11: 255.55548 | K11: 199.02551
A12: 2018 | B12: 5200 | C12: 3660 | D12: 4400 | E12: 3687.5 | G12: 2019 | H12: 355 | I12: 132.17423 | J12: 201.28955 | K12: 241.21627
A13: 2019 | B13: 6685 | C13: 4400 | D13: 3925 | E13: 3837.5 | G13: 2020 | H13: 553 | I13: 168.20219 | J13: 206.24107 | K13: 353.34171
A14: 2020 | B14: 6670 | C14: 4170 | D14: 3087.5 | E14: 3162.5 | G14: 2021 | H14: 457 | I14: 98.905659 | J14: 44.022623 | K14: 220.27176
A15: 2021 | B15: 7300 | C15: 4110 | D15: 3375 | E15: 3512.5 | G15: 2022 | H15: 155 | I15: 174.25147 | J15: 146.29688 | K15: 360.63556
A16: 2022 | B16: 8550 | C16: 4940 | D16: 4612.5 | E16: 4962.5 | G16: 2023 | H16: 212.5 | I16: 288.22139 | J16: 392.78011 | K16: 529.33676
A17: 2023 | B17: 9400 | C17: 5725 | D17: 5375 | E17: 6050
C20: DIVIDEN
A21: TAHUN | B21: BBCA | C21: BBRI | D21: BBNI | E21: BMRI
A22: 2013 | B22: 71 | C22: 225.232 | D22: 113.35 | E22: 199.33799
B23: 45
A24: 2014 | B24: 75 | C24: 257.3271 | D24: 145.71 | E24: 234.04825
B25: 50
A26: 2015 | B26: 98 | C26: 294.801 | D26: 144.54965 | E26: 212.91292
B27: 55
A28: 2016 | B28: 105 | C28: 311.6613 | D28: 122.53382 | E28: 261.44958
B29: 70
A30: 2017 | B30: 130 | C30: 428.60549 | D30: 212.80685 | E30: 266.26947
B31: 80
A32: 2018 | B32: 175 | C32: 106.74687 | D32: 255.55548 | E32: 199.02551
B33: 85
A34: 2019 | B34: 255 | C34: 132.17423 | D34: 201.28955 | E34: 241.21627
B35: 100
A36: 2020 | B36: 455 | C36: 168.20219 | D36: 206.24107 | E36: 353.34171
B37: 98
A38: 2021 | B38: 432 | C38: 98.905659 | D38: 44.022623 | E38: 220.27176
B39: 25
A40: 2022 | B40: 120 | C40: 174.25147 | D40: 146.29688 | E40: 360.63556
B41: 35
A42: 2023 | B42: 170 | C42: 57 | D42: 392.78011 | E42: 529.33676
B43: 42.5 | C43: 231.22139

Sheet TINGKAT RETURN
A1: TINGKAT RETURN PT. BANK CENTRAL ASIA TBK (BBCA) | I1: TINGKAT RETURN PT. BANK RAKYAT INDONESIA TBK (BBRI)
A2: PERIODE 2013-2023 | I2: PERIODE 2013-2023
A4: TAHUN | B4: Pit | C4: Pi(t-1) | D4: Di(t) | E4: Rit | I4: TAHUN | J4: Pit | K4: Pi(t-1) | L4: Di(t) | M4: Rit | O4: =VAR(E5:E15) -> 0.019616197
A5: 2013 | B5: 1920 | C5: 1820 | D5: 116 | E5: =(B5-C5+D5)/C5 -> 0.11868132 | I5: 2013 | J5: 1450 | K5: 1390 | L5: 225.232 | M5: =(J5-K5+L5)/K5 -> 0.20520288 | O5: =COVAR(E5:E15,M5:M15) -> 0.028474341
A6: 2014 | B6: 2625 | C6: 1920 | D6: 125 | E6: =(B6-C6+D6)/C6 -> 0.43229167 | I6: 2014 | J6: 2330 | K6: 1450 | L6: 257.3271 | M6: =(J6-K6+L6)/K6 -> 0.78436352
A7: 2015 | B7: 2660 | C7: 2625 | D7: 153 | E7: =(B7-C7+D7)/C7 -> 0.071619048 | I7: 2015 | J7: 2285 | K7: 2330 | L7: 294.801 | M7: =(J7-K7+L7)/K7 -> 0.10721073
A8: 2016 | B8: 3100 | C8: 2660 | D8: 175 | E8: =(B8-C8+D8)/C8 -> 0.23120301 | I8: 2016 | J8: 2335 | K8: 2285 | L8: 311.6613 | M8: =(J8-K8+L8)/K8 -> 0.15827628
A9: 2017 | B9: 4380 | C9: 3100 | D9: 210 | E9: =(B9-C9+D9)/C9 -> 0.48064516 | I9: 2017 | J9: 3640 | K9: 2335 | L9: 428.60549 | M9: =(J9-K9+L9)/K9 -> 0.74244346
A10: 2018 | B10: 5200 | C10: 4380 | D10: 260 | E10: =(B10-C10+D10)/C10 -> 0.24657534 | I10: 2018 | J10: 3660 | K10: 3640 | L10: 106.74687 | M10: =(J10-K10+L10)/K10 -> 0.034820569
A11: 2019 | B11: 6685 | C11: 5200 | D11: 355 | E11: =(B11-C11+D11)/C11 -> 0.35384615 | I11: 2019 | J11: 4400 | K11: 3660 | L11: 132.17423 | M11: =(J11-K11+L11)/K11 -> 0.23829897
A12: 2020 | B12: 6670 | C12: 6685 | D12: 553 | E12: =(B12-C12+D12)/C12 -> 0.080478684 | I12: 2020 | J12: 4170 | K12: 4400 | L12: 168.20219 | M12: =(J12-K12+L12)/K12 -> -0.014044957
A13: 2021 | B13: 7300 | C13: 6670 | D13: 457 | E13: =(B13-C13+D13)/C13 -> 0.16296852 | I13: 2021 | J13: 4110 | K13: 4170 | L13: 98.905659 | M13: =(J13-K13+L13)/K13 -> 0.0093298942
A14: 2022 | B14: 8550 | C14: 7300 | D14: 155 | E14: =(B14-C14+D14)/C14 -> 0.19246575 | I14: 2022 | J14: 4940 | K14: 4110 | L14: 174.25147 | M14: =(J14-K14+L14)/K14 -> 0.24434342
A15: 2023 | B15: 9400 | C15: 8550 | D15: 212.5 | E15: =(B15-C15+D15)/C15 -> 0.12426901 | I15: 2023 | J15: 5725 | K15: 4940 | L15: 288.22139 | M15: =(J15-K15+L15)/K15 -> 0.21725129
A18: TINGKAT RETURN PT. BANK NEGARA INDONESIA TBK (BBNI) | I18: TINGKAT RETURN PT. BANK MANDIRI (PERSERO) TBK (BMRI)
A19: PERIODE 2013-2023 | I19: PERIODE 2013-2023
A21: TAHUN | B21: Pit | C21: Pi(t-1) | D21: Di(t) | E21: Rit | I21: TAHUN | J21: Pit | K21: Pi(t-1) | L21: Di(t) | M21: Rit
A22: 2013 | B22: 1975 | C22: 1850 | D22: 113.35 | E22: =(B22-C22+D22)/C22 -> 0.12883784 | I22: 2013 | J22: 1962.5 | K22: 2025 | L22: 199.33799 | M22: =(J22-K22+L22)/K22 -> 0.067574316
A23: 2014 | B23: 3050 | C23: 1975 | D23: 145.71 | E23: =(B23-C23+D23)/C23 -> 0.61808101 | I23: 2014 | J23: 2693.75 | K23: 1962.5 | L23: 234.04825 | M23: =(J23-K23+L23)/K23 -> 0.49187172
A24: 2015 | B24: 2945 | C24: 3050 | D24: 144.54965 | E24: =(B24-C24+D24)/C24 -> 0.012967098 | I24: 2015 | J24: 2312.5 | K24: 2693.75 | L24: 212.91292 | M24: =(J24-K24+L24)/K24 -> -0.062491723
A25: 2016 | B25: 2762.5 | C25: 2945 | D25: 122.53382 | E25: =(B25-C25+D25)/C25 -> -0.020362031 | I25: 2016 | J25: 2893.75 | K25: 2312.5 | L25: 261.44958 | M25: =(J25-K25+L25)/K25 -> 0.36441063
A26: 2017 | B26: 4950 | C26: 2762.5 | D26: 212.80685 | E26: =(B26-C26+D26)/C26 -> 0.86888936 | I26: 2017 | J26: 4000 | K26: 2893.75 | L26: 266.26947 | M26: =(J26-K26+L26)/K26 -> 0.47430478
A27: 2018 | B27: 4400 | C27: 4950 | D27: 255.55548 | E27: =(B27-C27+D27)/C27 -> -0.059483741 | I27: 2018 | J27: 3687.5 | K27: 4000 | L27: 199.02551 | M27: =(J27-K27+L27)/K27 -> -0.028368622
A28: 2019 | B28: 3925 | C28: 4400 | D28: 201.28955 | E28: =(B28-C28+D28)/C28 -> -0.06220692 | I28: 2019 | J28: 3837.5 | K28: 3687.5 | L28: 241.21627 | M28: =(J28-K28+L28)/K28 -> 0.10609255
A29: 2020 | B29: 3087.5 | C29: 3925 | D29: 206.24107 | E29: =(B29-C29+D29)/C29 -> -0.1608303 | I29: 2020 | J29: 3162.5 | K29: 3837.5 | L29: 353.34171 | M29: =(J29-K29+L29)/K29 -> -0.08381975
A30: 2021 | B30: 3375 | C30: 3087.5 | D30: 44.022623 | E30: =(B30-C30+D30)/C30 -> 0.10737575 | I30: 2021 | J30: 3512.5 | K30: 3162.5 | L30: 220.27176 | M30: =(J30-K30+L30)/K30 -> 0.18032309
A31: 2022 | B31: 4612.5 | C31: 3375 | D31: 146.29688 | E31: =(B31-C31+D31)/C31 -> 0.41001389 | I31: 2022 | J31: 4962.5 | K31: 3512.5 | L31: 360.63556 | M31: =(J31-K31+L31)/K31 -> 0.51548343
A32: 2023 | B32: 5375 | C32: 4612.5 | D32: 392.78011 | E32: =(B32-C32+D32)/C32 -> 0.25046723 | I32: 2023 | J32: 6050 | K32: 4962.5 | L32: 529.33676 | M32: =(J32-K32+L32)/K32 -> 0.32581093

Sheet TOTAL TINGKAT RETURN
A1: TINGKAT RETURN (KEUNTUNGAN) TIAP-TIAP SAHAM
A2: PERIODE 2013-2023
A4: TAHUN | B4: NAMA SAHAM
B5: BBCA | C5: BBRI | D5: BBNI | E5: BMRI
A6: 2013 | B6: ='TINGKAT RETURN'!E5 -> 0.11868132 | C6: ='TINGKAT RETURN'!M5 -> 0.20520288 | D6: ='TINGKAT RETURN'!E22 -> 0.12883784 | E6: ='TINGKAT RETURN'!M22 -> 0.067574316
A7: 2014 | B7: ='TINGKAT RETURN'!E6 -> 0.43229167 | C7: ='TINGKAT RETURN'!M6 -> 0.78436352 | D7: ='TINGKAT RETURN'!E23 -> 0.61808101 | E7: ='TINGKAT RETURN'!M23 -> 0.49187172
A8: 2015 | B8: ='TINGKAT RETURN'!E7 -> 0.071619048 | C8: ='TINGKAT RETURN'!M7 -> 0.10721073 | D8: ='TINGKAT RETURN'!E24 -> 0.012967098 | E8: ='TINGKAT RETURN'!M24 -> -0.062491723
A9: 2016 | B9: ='TINGKAT RETURN'!E8 -> 0.23120301 | C9: ='TINGKAT RETURN'!M8 -> 0.15827628 | D9: ='TINGKAT RETURN'!E25 -> -0.020362031 | E9: ='TINGKAT RETURN'!M25 -> 0.36441063
A10: 2017 | B10: ='TINGKAT RETURN'!E9 -> 0.48064516 | C10: ='TINGKAT RETURN'!M9 -> 0.74244346 | D10: ='TINGKAT RETURN'!E26 -> 0.86888936 | E10: ='TINGKAT RETURN'!M26 -> 0.47430478
A11: 2018 | B11: ='TINGKAT RETURN'!E10 -> 0.24657534 | C11: ='TINGKAT RETURN'!M10 -> 0.034820569 | D11: ='TINGKAT RETURN'!E27 -> -0.059483741 | E11: ='TINGKAT RETURN'!M27 -> -0.028368622
A12: 2019 | B12: ='TINGKAT RETURN'!E11 -> 0.35384615 | C12: ='TINGKAT RETURN'!M11 -> 0.23829897 | D12: ='TINGKAT RETURN'!E28 -> -0.06220692 | E12: ='TINGKAT RETURN'!M28 -> 0.10609255
A13: 2020 | B13: ='TINGKAT RETURN'!E12 -> 0.080478684 | C13: ='TINGKAT RETURN'!M12 -> -0.014044957 | D13: ='TINGKAT RETURN'!E29 -> -0.1608303 | E13: ='TINGKAT RETURN'!M29 -> -0.08381975
A14: 2021 | B14: ='TINGKAT RETURN'!E13 -> 0.16296852 | C14: ='TINGKAT RETURN'!M13 -> 0.0093298942 | D14: ='TINGKAT RETURN'!E30 -> 0.10737575 | E14: ='TINGKAT RETURN'!M30 -> 0.18032309
A15: 2022 | B15: ='TINGKAT RETURN'!E14 -> 0.19246575 | C15: ='TINGKAT RETURN'!M14 -> 0.24434342 | D15: ='TINGKAT RETURN'!E31 -> 0.41001389 | E15: ='TINGKAT RETURN'!M31 -> 0.51548343
A16: 2023 | B16: ='TINGKAT RETURN'!E15 -> 0.12426901 | C16: ='TINGKAT RETURN'!M15 -> 0.21725129 | D16: ='TINGKAT RETURN'!E32 -> 0.25046723 | E16: ='TINGKAT RETURN'!M32 -> 0.32581093
A17: TOTAL | B17: =SUM(B6:B16) -> 2.4950437 | C17: =SUM(C6:C16) -> 2.7274961 | D17: =SUM(D6:D16) -> 2.0937492 | E17: =SUM(E6:E16) -> 2.3511914

Sheet EXPECTED RETURN
A1: EXPECTED RETURN TIAP-TIAP SAHAM
A2: PERIODE JANUARI 2022- DESEMBER 2022
A4: NAMA SAHAM | B4: TINGKAT RETURN | C4: N | D4: EXPECTED RETURN
A6: BBCA | B6: ='TOTAL TINGKAT RETURN'!B17 -> 2.4950437 | C6: 10 | D6: =B6/C6 -> 0.24950437
A7: BBRI | B7: ='TOTAL TINGKAT RETURN'!C17 -> 2.7274961 | C7: 10 | D7: =B7/C7 -> 0.27274961
A8: BBNI | B8: ='TOTAL TINGKAT RETURN'!D17 -> 2.0937492 | C8: 10 | D8: =B8/C8 -> 0.20937492
A9: BMRI | B9: ='TOTAL TINGKAT RETURN'!E17 -> 2.3511914 | C9: 10 | D9: =B9/C9 -> 0.23511914

Sheet DEVIASI STANDAR
A1: RESIKO TIAP-TIAP SAHAM (DEVIASI STANDAR)
A4: NAMA SAHAM | B4: TINGKAT RETURN | M4: EXPECTED RETURN | N4: VARIANS | O4: STANDAR DEVIASI
B5: 2013 | C5: 2014 | D5: 2015 | E5: 2016 | F5: 2017 | G5: 2018 | H5: 2019 | I5: 2020 | J5: 2021 | K5: 2022 | L5: 2023
A6: BBCA | B6: ='TOTAL TINGKAT RETURN'!B6 -> 0.11868132 | C6: ='TOTAL TINGKAT RETURN'!B7 -> 0.43229167 | D6: ='TOTAL TINGKAT RETURN'!B8 -> 0.071619048 | E6: ='TOTAL TINGKAT RETURN'!B9 -> 0.23120301 | F6: ='TOTAL TINGKAT RETURN'!B10 -> 0.48064516 | G6: ='TOTAL TINGKAT RETURN'!B11 -> 0.24657534 | H6: ='TOTAL TINGKAT RETURN'!B12 -> 0.35384615 | I6: ='TOTAL TINGKAT RETURN'!B13 -> 0.080478684 | J6: ='TOTAL TINGKAT RETURN'!B14 -> 0.16296852 | K6: ='TOTAL TINGKAT RETURN'!B15 -> 0.19246575 | L6: ='TOTAL TINGKAT RETURN'!B16 -> 0.12426901 | M6: ='EXPECTED RETURN'!D6 -> 0.24950437 | N6: =((B6-M6)^2+(C6-M6)^2+(D6-M6)^2+(E6-M6)^2+(F6-M6)^2+(G6-M6)^2+(H6-M6)^2+(I6-M6)^2+(J6-M6)^2+(K6-M6)^2+(L6-M6)^2)/10 -> 0.020182128 | O6: =SQRT(N6) -> 0.14206382
A7: BBRI | B7: ='TOTAL TINGKAT RETURN'!C6 -> 0.20520288 | C7: ='TOTAL TINGKAT RETURN'!C7 -> 0.78436352 | D7: ='TOTAL TINGKAT RETURN'!C8 -> 0.10721073 | E7: ='TOTAL TINGKAT RETURN'!C9 -> 0.15827628 | F7: ='TOTAL TINGKAT RETURN'!C10 -> 0.74244346 | G7: ='TOTAL TINGKAT RETURN'!C11 -> 0.034820569 | H7: ='TOTAL TINGKAT RETURN'!C12 -> 0.23829897 | I7: ='TOTAL TINGKAT RETURN'!C13 -> -0.014044957 | J7: ='TOTAL TINGKAT RETURN'!C14 -> 0.0093298942 | K7: ='TOTAL TINGKAT RETURN'!C15 -> 0.24434342 | L7: ='TOTAL TINGKAT RETURN'!C16 -> 0.21725129 | M7: ='EXPECTED RETURN'!D7 -> 0.27274961 | N7: =((B7-M7)^2+(C7-M7)^2+(D7-M7)^2+(E7-M7)^2+(F7-M7)^2+(G7-M7)^2+(H7-M7)^2+(I7-M7)^2+(J7-M7)^2+(K7-M7)^2+(L7-M7)^2)/10 -> 0.074075605 | O7: =SQRT(N7) -> 0.27216834
A8: BBNI | B8: ='TOTAL TINGKAT RETURN'!D6 -> 0.12883784 | C8: ='TOTAL TINGKAT RETURN'!D7 -> 0.61808101 | D8: ='TOTAL TINGKAT RETURN'!D8 -> 0.012967098 | E8: ='TOTAL TINGKAT RETURN'!D9 -> -0.020362031 | F8: ='TOTAL TINGKAT RETURN'!D10 -> 0.86888936 | G8: ='TOTAL TINGKAT RETURN'!D11 -> -0.059483741 | H8: ='TOTAL TINGKAT RETURN'!D12 -> -0.06220692 | I8: ='TOTAL TINGKAT RETURN'!D13 -> -0.1608303 | J8: ='TOTAL TINGKAT RETURN'!D14 -> 0.10737575 | K8: ='TOTAL TINGKAT RETURN'!D15 -> 0.41001389 | L8: ='TOTAL TINGKAT RETURN'!D16 -> 0.25046723 | M8: ='EXPECTED RETURN'!D8 -> 0.20937492 | N8: =((B8-M8)^2+(C8-M8)^2+(D8-M8)^2+(E8-M8)^2+(F8-M8)^2+(G8-M8)^2+(H8-M8)^2+(I8-M8)^2+(J8-M8)^2+(K8-M8)^2+(L8-M8)^2)/10 -> 0.10352833 | O8: =SQRT(N8) -> 0.32175818
A9: BMRI | B9: ='TOTAL TINGKAT RETURN'!E6 -> 0.067574316 | C9: ='TOTAL TINGKAT RETURN'!E7 -> 0.49187172 | D9: ='TOTAL TINGKAT RETURN'!E8 -> -0.062491723 | E9: ='TOTAL TINGKAT RETURN'!E9 -> 0.36441063 | F9: ='TOTAL TINGKAT RETURN'!E10 -> 0.47430478 | G9: ='TOTAL TINGKAT RETURN'!E11 -> -0.028368622 | H9: ='TOTAL TINGKAT RETURN'!E12 -> 0.10609255 | I9: ='TOTAL TINGKAT RETURN'!E13 -> -0.08381975 | J9: ='TOTAL TINGKAT RETURN'!E14 -> 0.18032309 | K9: ='TOTAL TINGKAT RETURN'!E15 -> 0.51548343 | L9: ='TOTAL TINGKAT RETURN'!E16 -> 0.32581093 | M9: ='EXPECTED RETURN'!D9 -> 0.23511914 | N9: =((B9-M9)^2+(C9-M9)^2+(D9-M9)^2+(E9-M9)^2+(F9-M9)^2+(G9-M9)^2+(H9-M9)^2+(I9-M9)^2+(J9-M9)^2+(K9-M9)^2+(L9-M9)^2)/10 -> 0.053411886 | O9: =SQRT(N9) -> 0.23111012

Sheet KOMBINASI
A1: KOMBINASI PORTOFOLIO SAHAM
A3: PORTOFOLIO | B3: KOMBINASI SAHAM
A4: 1 | B4: PT. BANK CENTRAL ASIA TBK (BBCA) dan PT. BANK RAKYAT INDONESIA (BBRI)
A5: 2 | B5: PT. BANK CENTRAL ASIA TBK (BBCA) dan PT. BANK NEGARA INDONESIA (BBNI)
A6: 3 | B6: PT. BANK CENTRAL ASIA TBK (BBCA) dan PT. BANK MANDIRI (PERSERO) TBK (BMRI)
A7: 4 | B7: PT. BANK RAKYAT INDONESIA (BBRI) dan PT. BANK NEGARA INDONESIA TBK (BBNI)
A8: 5 | B8: PT. BANK RAKYAT INDONESIA (BBRI) dan PT. BANK MANDIRI (PERSERO) TBK (BMRI)
A9: 6 | B9: PT. BANK NEGARA INDONESIA TBK (BBNI) dan PT. BANK MANDIRI (PERSERO) TBK (BMRI)

Sheet KOVARIAN ANTAR SAHAM
B3: KOMBINASI PORTOFOLIO 2 (BBCA-BBRI) | I3: KOMBINASI PORTOFOLIO 1 (BBCA-BBCA)
A5: TAHUN | B5: BBCA (Ra) | C5: BBRI (Rb) | D5: Ra-Era | E5: Rb-Erb | F5: (Ra-E(Ra).(Rb-E(Rb) | H5: TAHUN | I5: BBCA(Ra) | J5: BBCA(Rb) | K5: Ra-ERa | L5: Rb-Erb | M5: (Ra-ERa).(Rb-Erb)
A6: 2013 | B6: ='TINGKAT RETURN'!E5 -> 0.11868132 | C6: ='TINGKAT RETURN'!M5 -> 0.20520288 | D6: =B6-B18 -> -0.13082305 | E6: =C6-C18 -> -0.067546729 | F6: =D6*E6 -> 0.0088366688 | H6: 2013 | I6: =B6 -> 0.11868132 | J6: =B6 -> 0.11868132 | K6: =D6 -> -0.13082305 | L6: =D6 -> -0.13082305 | M6: =K6*L6 -> 0.01711467
A7: 2014 | B7: ='TINGKAT RETURN'!E6 -> 0.43229167 | C7: ='TINGKAT RETURN'!M6 -> 0.78436352 | D7: =B7-B18 -> 0.1827873 | E7: =C7-C18 -> 0.51161391 | F7: =D7*E7 -> 0.093516526 | H7: 2014 | I7: =B7 -> 0.43229167 | J7: =B7 -> 0.43229167 | K7: =D7 -> 0.1827873 | L7: =D7 -> 0.1827873 | M7: =K7*L7 -> 0.033411197
A8: 2015 | B8: ='TINGKAT RETURN'!E7 -> 0.071619048 | C8: ='TINGKAT RETURN'!M7 -> 0.10721073 | D8: =B8-B18 -> -0.17788532 | E8: =C8-C18 -> -0.16553888 | F8: =D8*E8 -> 0.029446936 | H8: 2015 | I8: =B8 -> 0.071619048 | J8: =B8 -> 0.071619048 | K8: =D8 -> -0.17788532 | L8: =D8 -> -0.17788532 | M8: =K8*L8 -> 0.031643186
A9: 2016 | B9: ='TINGKAT RETURN'!E8 -> 0.23120301 | C9: ='TINGKAT RETURN'!M8 -> 0.15827628 | D9: =B9-B18 -> -0.018301358 | E9: =C9-C18 -> -0.11447333 | F9: =D9*E9 -> 0.0020950173 | H9: 2016 | I9: =B9 -> 0.23120301 | J9: =B9 -> 0.23120301 | K9: =D9 -> -0.018301358 | L9: =D9 -> -0.018301358 | M9: =K9*L9 -> 0.00033493971
A10: 2017 | B10: ='TINGKAT RETURN'!E9 -> 0.48064516 | C10: ='TINGKAT RETURN'!M9 -> 0.74244346 | D10: =B10-B18 -> 0.2311408 | E10: =C10-C18 -> 0.46969386 | F10: =D10*E10 -> 0.10856541 | H10: 2017 | I10: =B10 -> 0.48064516 | J10: =B10 -> 0.48064516 | K10: =D10 -> 0.2311408 | L10: =D10 -> 0.2311408 | M10: =K10*L10 -> 0.053426067
A11: 2018 | B11: ='TINGKAT RETURN'!E10 -> 0.24657534 | C11: ='TINGKAT RETURN'!M10 -> 0.034820569 | D11: =B11-B18 -> -0.0029290232 | E11: =C11-C18 -> -0.23792904 | F11: =D11*E11 -> 0.00069689967 | H11: 2018 | I11: =B11 -> 0.24657534 | J11: =B11 -> 0.24657534 | K11: =D11 -> -0.0029290232 | L11: =D11 -> -0.0029290232 | M11: =K11*L11 -> 8.5791769e-06
A12: 2019 | B12: ='TINGKAT RETURN'!E11 -> 0.35384615 | C12: ='TINGKAT RETURN'!M11 -> 0.23829897 | D12: =B12-B18 -> 0.10434179 | E12: =C12-C18 -> -0.034450636 | F12: =D12*E12 -> -0.003594641 | H12: 2019 | I12: =B12 -> 0.35384615 | J12: =B12 -> 0.35384615 | K12: =D12 -> 0.10434179 | L12: =D12 -> 0.10434179 | M12: =K12*L12 -> 0.010887209
A13: 2020 | B13: ='TINGKAT RETURN'!E12 -> 0.080478684 | C13: ='TINGKAT RETURN'!M12 -> -0.014044957 | D13: =B13-B18 -> -0.16902568 | E13: =C13-C18 -> -0.28679456 | F13: =D13*E13 -> 0.048475647 | H13: 2020 | I13: =B13 -> 0.080478684 | J13: =B13 -> 0.080478684 | K13: =D13 -> -0.16902568 | L13: =D13 -> -0.16902568 | M13: =K13*L13 -> 0.028569681
A14: 2021 | B14: ='TINGKAT RETURN'!E13 -> 0.16296852 | C14: ='TINGKAT RETURN'!M13 -> 0.0093298942 | D14: =B14-B18 -> -0.08653585 | E14: =C14-C18 -> -0.26341971 | F14: =D14*E14 -> 0.022795249 | H14: 2021 | I14: =B14 -> 0.16296852 | J14: =B14 -> 0.16296852 | K14: =D14 -> -0.08653585 | L14: =D14 -> -0.08653585 | M14: =K14*L14 -> 0.0074884533
A15: 2022 | B15: ='TINGKAT RETURN'!E14 -> 0.19246575 | C15: ='TINGKAT RETURN'!M14 -> 0.24434342 | D15: =B15-B18 -> -0.057038612 | E15: =C15-C18 -> -0.028406183 | F15: =D15*E15 -> 0.0016202492 | H15: 2022 | I15: =B15 -> 0.19246575 | J15: =B15 -> 0.19246575 | K15: =D15 -> -0.057038612 | L15: =D15 -> -0.057038612 | M15: =K15*L15 -> 0.0032534033
A16: 2023 | B16: ='TINGKAT RETURN'!E15 -> 0.12426901 | C16: ='TINGKAT RETURN'!M15 -> 0.21725129 | D16: =B16-B18 -> -0.12523536 | E16: =C16-C18 -> -0.055498313 | F16: =D16*E16 -> 0.0069503512 | H16: 2023 | I16: =B16 -> 0.12426901 | J16: =B16 -> 0.12426901 | K16: =D16 -> -0.12523536 | L16: =D16 -> -0.12523536 | M16: =K16*L16 -> 0.015683895
A17: TOTAL | B17: =SUM(B6:B16) -> 2.4950437 | C17: =SUM(C6:C16) -> 2.7274961 | F17: =SUM(F6:F16) -> 0.31940431 | H17: TOTAL | I17: =SUM(I6:I16) -> 2.4950437 | J17: =SUM(J6:J16) -> 2.4950437 | M17: =SUM(M6:M16) -> 0.20182128
A18: EXPECTED RETURN | B18: =B17/10 -> 0.24950437 | C18: =C17/10 -> 0.27274961 | H18: EXPECTED RETURN | I18: =I17/10 -> 0.24950437 | J18: =J17/10 -> 0.24950437
A19: KOVARIAN | F19: =F17/10 -> 0.031940431 | H19: KOVARIAN | M19: =M17/10 -> 0.020182128
B21: KOMBINASI PORTOFOLIO 3 (BBCA-BBNI) | I21: KOMBINASI PORTOFOLIO 4 (BBCA-BMRI)
A23: TAHUN | B23: BBCA(Ra) | C23: BBNI(Rb) | D23: Ra-Era | E23: Rb-Erb | F23: (Ra-ERa).(Rb-ERb) | H23: TAHUN | I23: BBCA(Ra) | J23: BMRI(Rb) | K23: Ra-Era | L23: Rb-Erb | M23: (Ra-Era).((Rb-Erb)
A24: 2013 | B24: =B6 -> 0.11868132 | C24: ='TOTAL TINGKAT RETURN'!D6 -> 0.12883784 | D24: =D6 -> -0.13082305 | E24: =C24-C36 -> -0.080537081 | F24: =D24*E24 -> 0.010536106 | H24: 2013 | I24: =B24 -> 0.11868132 | J24: ='TOTAL TINGKAT RETURN'!E6 -> 0.067574316 | K24: =I24-I36 -> -0.13082305 | L24: =J24-J36 -> -0.16754482 | M24: =K24*L24 -> 0.021918724
A25: 2014 | B25: =B7 -> 0.43229167 | C25: ='TOTAL TINGKAT RETURN'!D7 -> 0.61808101 | D25: =D7 -> 0.1827873 | E25: =C25-C36 -> 0.40870609 | F25: =D25*E25 -> 0.074706284 | H25: 2014 | I25: =B25 -> 0.43229167 | J25: ='TOTAL TINGKAT RETURN'!E7 -> 0.49187172 | K25: =I25-I36 -> 0.1827873 | L25: =J25-J36 -> 0.25675258 | M25: =K25*L25 -> 0.046931112
A26: 2015 | B26: =B8 -> 0.071619048 | C26: ='TOTAL TINGKAT RETURN'!D8 -> 0.012967098 | D26: =D8 -> -0.17788532 | E26: =C26-C36 -> -0.19640782 | F26: =D26*E26 -> 0.034938068 | H26: 2015 | I26: =B26 -> 0.071619048 | J26: ='TOTAL TINGKAT RETURN'!E8 -> -0.062491723 | K26: =I26-I36 -> -0.17788532 | L26: =J26-J36 -> -0.29761086 | M26: =K26*L26 -> 0.052940602
A27: 2016 | B27: =B9 -> 0.23120301 | C27: ='TOTAL TINGKAT RETURN'!D9 -> -0.020362031 | D27: =D9 -> -0.018301358 | E27: =C27-C36 -> -0.22973695 | F27: =D27*E27 -> 0.0042044982 | H27: 2016 | I27: =B27 -> 0.23120301 | J27: ='TOTAL TINGKAT RETURN'!E9 -> 0.36441063 | K27: =I27-I36 -> -0.018301358 | L27: =J27-J36 -> 0.12929149 | M27: =K27*L27 -> -0.0023662099
A28: 2017 | B28: =B10 -> 0.48064516 | C28: ='TOTAL TINGKAT RETURN'!D10 -> 0.86888936 | D28: =D10 -> 0.2311408 | E28: =C28-C36 -> 0.65951444 | F28: =D28*E28 -> 0.15244069 | H28: 2017 | I28: =B28 -> 0.48064516 | J28: ='TOTAL TINGKAT RETURN'!E10 -> 0.47430478 | K28: =I28-I36 -> 0.2311408 | L28: =J28-J36 -> 0.23918565 | M28: =K28*L28 -> 0.055285561
A29: 2018 | B29: =B11 -> 0.24657534 | C29: ='TOTAL TINGKAT RETURN'!D11 -> -0.059483741 | D29: =D11 -> -0.0029290232 | E29: =C29-C36 -> -0.26885866 | F29: =D29*E29 -> 0.00078749325 | H29: 2018 | I29: =B29 -> 0.24657534 | J29: ='TOTAL TINGKAT RETURN'!E11 -> -0.028368622 | K29: =I29-I36 -> -0.0029290232 | L29: =J29-J36 -> -0.26348776 | M29: =K29*L29 -> 0.00077176176
A30: 2019 | B30: =B12 -> 0.35384615 | C30: ='TOTAL TINGKAT RETURN'!D12 -> -0.06220692 | D30: =D12 -> 0.10434179 | E30: =C30-C36 -> -0.27158184 | F30: =D30*E30 -> -0.028337335 | H30: 2019 | I30: =B30 -> 0.35384615 | J30: ='TOTAL TINGKAT RETURN'!E12 -> 0.10609255 | K30: =I30-I36 -> 0.10434179 | L30: =J30-J36 -> -0.12902659 | M30: =K30*L30 -> -0.013462865
A31: 2020 | B31: =B13 -> 0.080478684 | C31: ='TOTAL TINGKAT RETURN'!D13 -> -0.1608303 | D31: =D13 -> -0.16902568 | E31: =C31-C36 -> -0.37020522 | F31: =D31*E31 -> 0.06257419 | H31: 2020 | I31: =B31 -> 0.080478684 | J31: ='TOTAL TINGKAT RETURN'!E13 -> -0.08381975 | K31: =I31-I36 -> -0.16902568 | L31: =J31-J36 -> -0.31893889 | M31: =K31*L31 -> 0.053908863
A32: 2021 | B32: =B14 -> 0.16296852 | C32: ='TOTAL TINGKAT RETURN'!D14 -> 0.10737575 | D32: =D14 -> -0.08653585 | E32: =C32-C36 -> -0.10199917 | F32: =D32*E32 -> 0.0088265849 | H32: 2021 | I32: =B32 -> 0.16296852 | J32: ='TOTAL TINGKAT RETURN'!E14 -> 0.18032309 | K32: =I32-I36 -> -0.08653585 | L32: =J32-J36 -> -0.054796049 | M32: =K32*L32 -> 0.0047418227
A33: 2022 | B33: =B15 -> 0.19246575 | C33: ='TOTAL TINGKAT RETURN'!D15 -> 0.41001389 | D33: =D15 -> -0.057038612 | E33: =C33-C36 -> 0.20063897 | F33: =D33*E33 -> -0.011444169 | H33: 2022 | I33: =B33 -> 0.19246575 | J33: ='TOTAL TINGKAT RETURN'!E15 -> 0.51548343 | K33: =I33-I36 -> -0.057038612 | L33: =J33-J36 -> 0.2803643 | M33: =K33*L33 -> -0.01599159
A34: 2023 | B34: =B16 -> 0.12426901 | C34: ='TOTAL TINGKAT RETURN'!D16 -> 0.25046723 | D34: =D16 -> -0.12523536 | E34: =C34-C36 -> 0.041092314 | F34: =D34*E34 -> -0.0051462107 | H34: 2023 | I34: =B34 -> 0.12426901 | J34: ='TOTAL TINGKAT RETURN'!E16 -> 0.32581093 | K34: =I34-I36 -> -0.12523536 | L34: =J34-J36 -> 0.090691798 | M34: =K34*L34 -> -0.01135782
A35: TOTAL | B35: =SUM(B24:B34) -> 2.4950437 | C35: =SUM(C24:C34) -> 2.0937492 | F35: =SUM(F24:F34) -> 0.3040862 | H35: TOTAL | I35: =SUM(I24:I34) -> 2.4950437 | J35: =SUM(J24:J34) -> 2.3511914 | M35: =SUM(M24:M34) -> 0.19331996
A36: EXPECTED RETURN | B36: =B35/10 -> 0.24950437 | C36: =C35/10 -> 0.20937492 | H36: EXEPECTED RETURN | I36: =I35/10 -> 0.24950437 | J36: =J35/10 -> 0.23511914
A37: KOVARIAN | F37: =F35/10 -> 0.03040862 | H37: KOVARIAN | M37: =M35/10 -> 0.019331996
B39: KOMBINASI PORTOFOLIO 5 (BBRI-BBRI) | I39: KOMBINASI PORTOFOLIO 6 (BBRI-BBNI)
A41: TAHUN | B41: BBRI(Ra) | C41: BBRI(Rb) | D41: (Ra-ERa) | E41: (Rb-ERb) | F41: (Ra-ERa).(Rb-ERb) | H41: TAHUN | I41: BBRI(Ra) | J41: BBNI(Rb) | K41: (Ra-ERa) | L41: (Rb-Erb) | M41: (Ra-ERa).(Rb-ERb)
A42: 2013 | B42: =C6 -> 0.20520288 | C42: =B42 -> 0.20520288 | D42: =E6 -> -0.067546729 | E42: =D42 -> -0.067546729 | F42: =D42*E42 -> 0.0045625605 | H42: 2013 | I42: =B42 -> 0.20520288 | J42: =C24 -> 0.12883784 | K42: =D42 -> -0.067546729 | L42: =E24 -> -0.080537081 | M42: =K42*L42 -> 0.0054400163
A43: 2014 | B43: =C7 -> 0.78436352 | C43: =B43 -> 0.78436352 | D43: =E7 -> 0.51161391 | E43: =D43 -> 0.51161391 | F43: =D43*E43 -> 0.26174879 | H43: 2014 | I43: =B43 -> 0.78436352 | J43: =C25 -> 0.61808101 | K43: =D43 -> 0.51161391 | L43: =E25 -> 0.40870609 | M43: =K43*L43 -> 0.20909972
A44: 2015 | B44: =C8 -> 0.10721073 | C44: =B44 -> 0.10721073 | D44: =E8 -> -0.16553888 | E44: =D44 -> -0.16553888 | F44: =D44*E44 -> 0.02740312 | H44: 2015 | I44: =B44 -> 0.10721073 | J44: =C26 -> 0.012967098 | K44: =D44 -> -0.16553888 | L44: =E26 -> -0.19640782 | M44: =K44*L44 -> 0.03251313
A45: 2016 | B45: =C9 -> 0.15827628 | C45: =B45 -> 0.15827628 | D45: =E9 -> -0.11447333 | E45: =D45 -> -0.11447333 | F45: =D45*E45 -> 0.013104142 | H45: 2016 | I45: =B45 -> 0.15827628 | J45: =C27 -> -0.020362031 | K45: =D45 -> -0.11447333 | L45: =E27 -> -0.22973695 | M45: =K45*L45 -> 0.026298753
A46: 2017 | B46: =C10 -> 0.74244346 | C46: =B46 -> 0.74244346 | D46: =E10 -> 0.46969386 | E46: =D46 -> 0.46969386 | F46: =D46*E46 -> 0.22061232 | H46: 2017 | I46: =B46 -> 0.74244346 | J46: =C28 -> 0.86888936 | K46: =D46 -> 0.46969386 | L46: =E28 -> 0.65951444 | M46: =K46*L46 -> 0.30976988
A47: 2018 | B47: =C11 -> 0.034820569 | C47: =B47 -> 0.034820569 | D47: =E11 -> -0.23792904 | E47: =D47 -> -0.23792904 | F47: =D47*E47 -> 0.056610227 | H47: 2018 | I47: =B47 -> 0.034820569 | J47: =C29 -> -0.059483741 | K47: =D47 -> -0.23792904 | L47: =E29 -> -0.26885866 | M47: =K47*L47 -> 0.063969282
...

Sheet KOEFISIEN ANTAR SAHAM
H3: PORTOFOLIO | I3: ∑Ri | J3: ∑Rj | K3: ∑Ri² | L3: ∑Rj² | M3: (∑Ri).(∑Rj) | N3: Pi,j | O3: Pi,j
H4: 1 | I4: ='EXPECTED RETURN'!$B$6 -> 2.4950437 | J4: ='EXPECTED RETURN'!B6 -> 2.4950437 | K4: =I4^2 -> 6.2252428 | L4: =J4^2 -> 6.2252428 | M4: =I4*J4 -> 6.2252428 | N4: =(10*M4-(J4)-I4)/SQRT((10*K4-(J4)^2)*(10*L4-(J4)^2)) -> 1.0220456 | O4: 1
H5: 2 | I5: =I4 -> 2.4950437 | J5: ='EXPECTED RETURN'!B7 -> 2.7274961 | K5: =I5^2 -> 6.2252428 | L5: =J5^2 -> 7.4392348 | M5: =I5*J5 -> 6.8052217 | N5: =(10*M5-(J5)-I5)/SQRT((10*K5-(J5)^2)*(10*L5-(J5)^2)) -> 1.0371388 | O5: 1
H6: 3 | I6: =I5 -> 2.4950437 | J6: ='EXPECTED RETURN'!B8 -> 2.0937492 | K6: =I6^2 -> 6.2252428 | L6: =J6^2 -> 4.3837856 | M6: =I6*J6 -> 5.2239956 | N6: =(10*M6-(J6)-I6)/SQRT((10*K6-(J6)^2)*(10*L6-(J6)^2)) -> 0.99725437 | O6: 1
H7: 4 | I7: =I6 -> 2.4950437 | J7: ='EXPECTED RETURN'!B9 -> 2.3511914 | K7: =I7^2 -> 6.2252428 | L7: =J7^2 -> 5.5281008 | M7: =I7*J7 -> 5.8663251 | N7: =(10*M7-(J7)-I7)/SQRT((10*K7-(J7)^2)*(10*L7-(J7)^2)) -> 1.0130379 | O7: 1
H8: 5 | I8: ='EXPECTED RETURN'!$B$7 -> 2.7274961 | J8: =I8 -> 2.7274961 | K8: =I8^2 -> 7.4392348 | L8: =J8^2 -> 7.4392348 | M8: =I8*J8 -> 7.4392348 | N8: =(10*M8-(J8)-I8)/SQRT((10*K8-(J8)^2)*(10*L8-(J8)^2)) -> 1.0296363 | O8: 1
H9: 6 | I9: =I8 -> 2.7274961 | J9: ='EXPECTED RETURN'!B8 -> 2.0937492 | K9: =I9^2 -> 7.4392348 | L9: =J9^2 -> 4.3837856 | M9: =I9*J9 -> 5.7106927 | N9: =(10*M9-(J9)-I9)/SQRT((10*K9-(J9)^2)*(10*L9-(J9)^2)) -> 0.99485843 | O9: 1
H10: 7 | I10: =I9 -> 2.7274961 | J10: ='EXPECTED RETURN'!B9 -> 2.3511914 | K10: =I10^2 -> 7.4392348 | L10: =J10^2 -> 5.5281008 | M10: =I10*J10 -> 6.4128652 | N10: =(10*M10-(J10)-I10)/SQRT((10*K10-(J10)^2)*(10*L10-(J10)^2)) -> 1.0088196 | O10: 1
H11: 8 | I11: ='EXPECTED RETURN'!$B$8 -> 2.0937492 | J11: =I11 -> 2.0937492 | K11: =I11^2 -> 4.3837856 | L11: =J11^2 -> 4.3837856 | M11: =I11*J11 -> 4.3837856 | N11: =(10*M11-(J11)-I11)/SQRT((10*K11-(J11)^2)*(10*L11-(J11)^2)) -> 1.0049751 | O11: 1
H12: 9 | I12: =I11 -> 2.0937492 | J12: ='EXPECTED RETURN'!B9 -> 2.3511914 | K12: =I12^2 -> 4.3837856 | L12: =J12^2 -> 5.5281008 | M12: =I12*J12 -> 4.922805 | N12: =(10*M12-(J12)-I12)/SQRT((10*K12-(J12)^2)*(10*L12-(J12)^2)) -> 1.0257708 | O12: 1
H13: 10 | I13: ='EXPECTED RETURN'!$B$9 -> 2.3511914 | J13: =I13 -> 2.3511914 | K13: =I13^2 -> 5.5281008 | L13: =J13^2 -> 5.5281008 | M13: =I13*J13 -> 5.5281008 | N13: =(10*M13-(J13)-I13)/SQRT((10*K13-(J13)^2)*(10*L13-(J13)^2)) -> 1.0165964 | O13: 1

Sheet MAX & MVP
A2: PORTOFOLIO | B2: STANDAR DEVIASI (σ) | C2: Expected Return | D2: PORTOFOLIO | E2: STANDAR DEVIASI (σ) | F2: EXPECETED RETURN
A3: BBCA | B3: ='DEVIASI STANDAR'!#REF! -> #REF! | C3: ='EXPECTED RETURN'!D6 -> 0.24950437 | D3: 1 | E3: =SQRT(1.02205) -> 1.0109649 | F3: =C3 -> 0.24950437
A4: BBRI | B4: ='DEVIASI STANDAR'!#REF! -> #REF! | C4: ='EXPECTED RETURN'!D7 -> 0.27274961 | D4: 2 | E4: =SQRT(1.03714) -> 1.0184007 | F4: =C3 -> 0.24950437
A5: BBNI | B5: ='DEVIASI STANDAR'!#REF! -> #REF! | C5: ='EXPECTED RETURN'!D8 -> 0.20937492 | D5: 3 | E5: =SQRT(0.99725) -> 0.99862405 | F5: =C3 -> 0.24950437
A6: BMRI | B6: ='DEVIASI STANDAR'!#REF! -> #REF! | C6: ='EXPECTED RETURN'!D9 -> 0.23511914 | D6: 4 | E6: =SQRT(1.01304) -> 1.0064989 | F6: =C3 -> 0.24950437
A7: MAX | B7: =MAX(B3:B6) -> #REF! | C7: =MAX(C3:C6) -> 0.27274961 | D7: 5 | E7: =SQRT(1.02964) -> 1.0147118 | F7: =C4 -> 0.27274961
D8: 6 | E8: =SQRT(0.99486) -> 0.99742669 | F8: =C4 -> 0.27274961
D9: 7 | E9: =SQRT(1.00882) -> 1.0044003 | F9: =C4 -> 0.27274961
D10: 8 | E10: =SQRT(1.00498) -> 1.0024869 | F10: =C5 -> 0.20937492
D11: 9 | E11: =SQRT(1.02577) -> 1.012803 | F11: =C5 -> 0.20937492
D12: 10 | E12: =SQRT(1.0166) -> 1.0082658 | F12: =C6 -> 0.23511914
D13: MVP | E13: =MIN(E3:E12) -> 0.99742669 | F13: =MIN(F3:F12) -> 0.20937492

Sheet PROPORSI DANA
A3: NAMA SAHAM | B3: EXPECTED RETURN | C3: STANDAR DEVIASI | D3: E(R):σ | E3: PROPORSI DANA
A5: BBCA | B5: ='EXPECTED RETURN'!D6 -> 0.24950437 | C5: ='DEVIASI STANDAR'!O6 -> 0.14206382 | D5: =B5/C5 -> 1.7562837
A6: BBRI | B6: ='EXPECTED RETURN'!D7 -> 0.27274961 | C6: ='DEVIASI STANDAR'!O7 -> 0.27216834 | D6: =B6/C6 -> 1.0021357
A7: BBNI | B7: ='EXPECTED RETURN'!D8 -> 0.20937492 | C7: ='DEVIASI STANDAR'!O8 -> 0.32175818 | D7: =B7/C7 -> 0.65072135
A8: BMRI | B8: ='EXPECTED RETURN'!D9 -> 0.23511914 | C8: ='DEVIASI STANDAR'!O9 -> 0.23111012 | D8: =B8/C8 -> 1.0173468

Sheet RISIKO PORTOFOLIO  SAHAM 

Sheet TINGKAT KEUNTUNGA DAN RESIKO

Sheet PORTOFOLIO EFISIEN & OPTIMAL
